Traceback (most recent call last):
  File "/Users/apple/Desktop/DataEngineeringBootCamp/GithubProfile/jackie-yt-wang/scripts/update_weather.py", line 28, in <module>
    city = weather_data['name']
           ~~~~~~~~~~~~^^^^^^^^
KeyError: 'name'
ack (most recent call last):
  File "/Users/apple/Desktop/DataEngineeringBootCamp/GithubProfile/jackie-yt-wang/scripts/update_weather.py", line 28, in <module>
    city = weather_data['name']
           ~~~~~~~~~~~~^^^^^^^^
KeyError: 'name'
PYTHON RUNNING FAILED
[ERROR:] RETURN CODE:  1
[ERROR:] REFER TO THE LOG FOR THE REASON FOR THE FAILURE.
